2020-09-25 23:20:41,087 [INFO ]  Starting Rasa server on http://localhost:5005
2020-09-25 23:20:46,159 [INFO ]  Rasa server is up and running.
2020-09-25 23:21:05,970 [ERROR]  Exception occurred while handling uri: 'http://localhost:5005/webhooks'
Traceback (most recent call last):
  File "/usr/local/lib/python3.7/site-packages/sanic/app.py", line 940, in handle_request
    handler, args, kwargs, uri, name = self.router.get(request)
  File "/usr/local/lib/python3.7/site-packages/sanic/router.py", line 411, in get
    return self._get(request.path, request.method, "")
  File "/usr/local/lib/python3.7/site-packages/sanic/router.py", line 475, in _get
    raise NotFound("Requested URL {} not found".format(url))
sanic.exceptions.NotFound: Requested URL /webhooks not found
2020-09-25 23:21:16,405 [ERROR]  Exception occurred while handling uri: 'http://localhost:5005/webhooks/myio/webhook'
Traceback (most recent call last):
  File "/usr/local/lib/python3.7/site-packages/sanic/app.py", line 940, in handle_request
    handler, args, kwargs, uri, name = self.router.get(request)
  File "/usr/local/lib/python3.7/site-packages/sanic/router.py", line 411, in get
    return self._get(request.path, request.method, "")
  File "/usr/local/lib/python3.7/site-packages/sanic/router.py", line 475, in _get
    raise NotFound("Requested URL {} not found".format(url))
sanic.exceptions.NotFound: Requested URL /webhooks/myio/webhook not found
2020-09-25 23:22:16,397 [ERROR]  Exception occurred while handling uri: unknown
NoneType: None
2020-09-26 10:43:19,555 [ERROR]  Exception occurred while handling uri: 'http://localhost:5005/webhooks/myio/webhook'
Traceback (most recent call last):
  File "/usr/local/lib/python3.7/site-packages/sanic/app.py", line 940, in handle_request
    handler, args, kwargs, uri, name = self.router.get(request)
  File "/usr/local/lib/python3.7/site-packages/sanic/router.py", line 411, in get
    return self._get(request.path, request.method, "")
  File "/usr/local/lib/python3.7/site-packages/sanic/router.py", line 475, in _get
    raise NotFound("Requested URL {} not found".format(url))
sanic.exceptions.NotFound: Requested URL /webhooks/myio/webhook not found
2020-09-26 10:44:19,521 [ERROR]  Exception occurred while handling uri: unknown
NoneType: None
